<?xml version="1.0"?>
<mujoco model="ur5">
    <compiler angle="radian" coordinate="local" eulerseq="xyz" />
    <option cone="elliptic" gravity="0 0 0" impratio="5" timestep="0.001" tolerance="1e-10" />
    <default class="main">
        <joint damping="0" armature="1" />
        <geom condim="4" solimp="0.99 0.99 0.01" solref="0.01 1" />
        <default class="arm1">
            <joint damping="0" />
        </default>
        <default class="arm2">
            <joint damping="0" />
        </default>
        <default class="gripper">
            <geom friction="1.0 0.5 0.5" contype="1" conaffinity="1" />
        </default>

        <default class="handle">
            <geom friction="1.0 0.5 0.5" contype="1" conaffinity="1" />
        </default>
    </default>


    <include file="../common/visual.xml" />
    <include file="../common/skybox.xml" />
    <include file="../common/materials.xml" />
    <include file="asset.xml" />

    <worldbody>
        <!-- <geom name="floor" size="5 5 .2" type="plane" material="grid" /> -->
        <camera mode="targetbody" name="cam_to_dockingring" pos="4 4 7" target="chasersat" />
        <light dir="0 0 -1" directional="true" name="light1" pos="0 -1 6" />
        <light dir="0 0 -1" directional="true" name="light2" pos="0 1 6" />

        <body name="chasersat" pos="0 0 0">
            <freejoint name="chasersat:joint" />
            <geom name="chasersat" mass="419.8441" pos="0 0 0" size="0.8726 0.8726 0.8726" type="box" />
            <site name="chasersat" pos="0 0 0" euler="0 0 0" size="0.01 0.01 0.01" type="box" />
            <site name="force_torque_site" pos="0 0 0" type="sphere" size="0.01"/>

            <!--  Camera  -->
            <body name="camera_body" pos="0 0.8726 0">
                <camera name="camera" mode="fixed" fovy="120"/>
            </body>

            <body name="chasersat_solar_panel_left" pos="0 -1.2 0" euler="0 0 1.57">
                <geom name="chasersat_solar_panel_left" type="box" size="1.5 0.05 0.5" mass="5" rgba="0.2 0.2 0.8 1"/>
            </body>
            <body name="chasersat_solar_panel_right" pos="0 1.2 0" euler="0 0 1.57">
                <geom name="chasersat_solar_panel_right" type="box" size="1.5 0.05 0.5" mass="5" rgba="0.2 0.2 0.8 1"/>
            </body>

            <body name="chasersat_base" pos="0.67 -0.67 0.9526">
                <geom name="chasersat_base" mass="10" pos="0 0 -0.04" size="0.1 0.1 0.04" type="box" />
                <body name="base_link" pos="0 0 0" euler="0 0 3.1415927">
                    <!--base_link is fixed in the base so that the motion of the arm will affect the base-->
                    <inertial pos="-0.00083 0 0.00758" mass="4" diaginertia="0.00443333 0.00443333 0.0072" />
                    <geom name="v_base_link" type="mesh" group="1" mesh="v_base" euler="0 0 -1.5707963" />

                    <!-- joint 1 : a joint creates motion degrees of freedom between the body where it is defined and the body's parent
                        joint 1 defines the relation of the motions between link1 and link0-->
                    <body name="shoulder_link" pos="0 0 0.089159" euler="1.5707963 0 0">
                        <inertial pos="0 -0.02561 0.00193" mass="3.7" diaginertia="0.0067 0.0064 0.0067" />
                        <joint class="arm1" name="arm:shoulder_pan_joint" axis="0 1 0" pos="0 -0.02561 0" />
                        <geom name="v_shoulder_link" type="mesh" group="1" mesh="v_shoulder" euler="1.5707963 3.1415927 0" />
                        <site name="shoulder_site" pos="0 0 .03" type="box" size=".02 .02 .02" />

                        <body name="upper_arm_link" pos="-0.425 0 0">
                            <inertial pos="0.2125 0 0.11336" mass="8.393" diaginertia="0.0149 0.3564 0.3553" />
                            <joint class="arm1" name="arm:shoulder_lift_joint" axis="0 0 1" pos="0.425 0 0.13585" />
                            <geom name="v_upper_arm_link" type="mesh" group="1" mesh="v_upperarm" pos="0.425 0 0.13585" euler="1.5707963 -1.5707963 0" />
                            <site name="upperarm_site" pos="0 0 .03" type="box" size=".02 .02 .02" />

                            <body name="forearm_link" pos="-0.39225 0 0">
                                <inertial pos="0.11993 0 0.0265" mass="2.275" fullinertia="0.0025 0.0551 0.0546 0 0.0034 0" />
                                <joint class="arm1" name="arm:elbow_joint" pos="0.39225 0 0.13585" axis="0 0 1" />
                                <geom name="v_forearm_link" type="mesh" group="1" mesh="v_forearm" pos="0.39225 0 0.0161" euler="1.5707963 -1.5707963 0" />
                                <site name="forearm_site" pos="0 0 .03" type="box" size=".02 .02 .02" />

                                <body name="wrist_1_link" pos="0 0 0.093" euler="1.5707963 0 0">
                                    <inertial pos="0 -0.0018 0.01634" mass="1.219" diaginertia="0.0012 0.0012 0.0009" />
                                    <joint class="arm2" name="arm:wrist_1_joint" pos="0 -0.093 0" axis="0 1 0" />
                                    <geom name="v_wrist_1_link" type="mesh" group="1" mesh="v_wrist1" pos="0 -0.093 0" />
                                    <site name="wrist1_site" pos="0 0 .03" type="box" size=".01 .01 .01" />

                                    <body name="wrist_2_link" pos="0 0 0.09465" euler="-1.5707963 0 0">
                                        <inertial pos="0 0.0018 0.01634" mass="1.219" diaginertia="0.0012 0.0012 0.0009" />
                                        <joint class="arm2" name="arm:wrist_2_joint" pos="0 0.09465 0" axis="0 -1 0" />
                                        <geom name="v_wrist_2_link" type="mesh" group="1" mesh="v_wrist2" pos="0 0.09465 0" euler="1.5707963 0 0" />
                                        <site name="wrist2_site" pos="0 0 .03" type="box" size=".01 .01 .01" />

                                        <body name="wrist_3_link" pos="0 0 0.0823">
                                            <inertial pos="0 0 -0.01159" mass="0.1879" diaginertia="0.0000884489143 0.0000884489143 0.000138534912" />
                                            <joint class="arm2" name="arm:wrist_3_joint" pos="0 0 -0.0823" axis="0 0 1" />
                                            <geom name="v_wrist_3_link" type="mesh" group="1" mesh="v_wrist3" pos="0 0 -0.0823" euler="1.5707963 0 0" />
                                            <site name="wrist3_site" pos="0 0 .03" type="box" size=".01 .01 .01" />

                                            <body name="gripper_base" pos="0 0 0.03">
                                                <site name="gripper_frame:x" pos="0.0618 0 0" size="0.01 0.0618" type="cylinder" rgba="1 0 0 1" euler="0 1.5707963 0" />
                                                <site name="gripper_frame:y" pos="0 0.0618 0" size="0.01 0.0618" type="cylinder" rgba="0 1 0 1" euler="-1.5707963 0 0" />
                                                <site name="gripper_frame:z" pos="0 0 0.0618" size="0.01 0.0618" type="cylinder" rgba="0 0 1 1" />
                                                <!-- left gripper -->
                                                <body name="left_gripper" pos="0.02 0 0">
                                                    <joint name="left_gripper_joint" type="slide" axis="1 0 0" range="0 0.02" />
                                                    <geom class="gripper" name="left_gripper_geom" type="box" size="0.01 0.01 0.05" pos="0.01 0 0" />
                                                </body>
                                                <!-- right gripper -->
                                                <body name="right_gripper" pos="-0.02 0 0">
                                                    <joint name="right_gripper_joint" type="slide" axis="1 0 0" range="-0.02 0" />
                                                    <geom class="gripper" name="right_gripper_geom" type="box" size="0.01 0.01 0.05" pos="-0.01 0 0" />
                                                </body>
                                            </body>
                                        </body>
                                    </body>
                                </body>
                            </body>
                        </body>
                    </body>
                </body>
            </body>
        </body>

        <body name="targetsat" pos="3 3 3" euler="0 0 3.1415927">
            <freejoint name="targetsat:joint"/>
            <geom name="targetsat" mass="79" pos="0 0 0" size="0.5 0.5 0.5" type="box"/>
            <site name="targetsat" pos="0 0 0" euler="0 0 0" size="0.01 0.01 0.01" type="box"/>
            <body name="targetsat_base" pos="0.54 0 0" euler="0 1.5707963 1.5707963">
                <geom name="targetsat_base" mass="2" pos="0 0 -0.04" size="0.3090 0.04" type="cylinder"/>
                <body name="target_frame" pos="0 0 0.1" euler="0 3.1415927 0">
                    <site name="target_frame:x" pos="0.0618 0 0" size="0.01 0.0618" type="cylinder" rgba="1 0 0 1" euler="0 1.5707963 0" />
                    <site name="target_frame:y" pos="0 0.0618 0" size="0.01 0.0618" type="cylinder" rgba="0 1 0 1" euler="-1.5707963 0 0" />
                    <site name="target_frame:z" pos="0 0 0.0618" size="0.01 0.0618" type="cylinder" rgba="0 0 1 1"/>
                </body>
            </body>

            <body name="handle" pos="0.5 0 0" euler="0 1.57 0">
                <geom class="handle" name="handle_geom" type="cylinder" size="0.02 0.25" pos="0 0 0" euler="0 0 0" rgba="0.8 0.0 0.0 1" mass="1"/>
                <site name="handle_site" pos="0 0 0.25" size="0.02" type="sphere" rgba="0.8 0.8 0.8 1"/>
            </body>

            <body name="targetsat_solar_panel_left" pos="0 -0.8 0" euler="0 0 1.57">
                <geom name="targetsat_solar_panel_left" type="box" size="0.8 0.05 0.25" mass="3" rgba="0.2 0.2 0.8 1"/>
            </body>
            <body name="targetsat_solar_panel_right" pos="0 0.8 0" euler="0 0 1.57">
                <geom name="targetsat_solar_panel_right" type="box" size="0.8 0.05 0.25" mass="3" rgba="0.2 0.2 0.8 1"/>
            </body>
        </body>
    </worldbody>

    <!-- scalar_force = gain_term * (act or ctrl) + bias_term -->
    <!-- default: fixed	gain_term = gainprm[0] -->
    <!-- default: none	bias_term = 0 -->
    <!--         affine	bias_term = biasprm[0] + biasprm[1]*length + biasprm[2]*velocity -->
    <actuator>
        <general name="x_force" site="force_torque_site" gear="1 0 0 0 0 0"
            gaintype="affine" gainprm="1" biastype="affine" biasprm="0 0 0" forcelimited="true" forcerange="-25 25"/>
        <general name="y_force" site="force_torque_site" gear="0 1 0 0 0 0"
            gaintype="affine" gainprm="1" biastype="affine" biasprm="0 0 0" forcelimited="true" forcerange="-25 25"/>
        <general name="z_force" site="force_torque_site" gear="0 0 1 0 0 0"
            gaintype="affine" gainprm="1" biastype="affine" biasprm="0 0 0" forcelimited="true" forcerange="-25 25"/>
        <general name="x_torque" site="force_torque_site" gear="0 0 0 1 0 0"
            gaintype="affine" gainprm="1" biastype="affine" biasprm="0 0 0" forcelimited="true" forcerange="-10 10"/>
        <general name="y_torque" site="force_torque_site" gear="0 0 0 0 1 0"
            gaintype="affine" gainprm="1" biastype="affine" biasprm="0 0 0" forcelimited="true" forcerange="-10 10"/>
        <general name="z_torque" site="force_torque_site" gear="0 0 0 0 0 1"
            gaintype="affine" gainprm="1" biastype="affine" biasprm="0 0 0" forcelimited="true" forcerange="-10 10"/>

        <!-- 使用简单的位置控制器 -->
        
        <position name="arm:shoulder_pan_T" joint="arm:shoulder_pan_joint" ctrllimited="true" ctrlrange="-2.0942 2.0942" kp="1"/>
        <position name="arm:shoulder_lift_T" joint="arm:shoulder_lift_joint" ctrllimited="true" ctrlrange="-2.0942 2.0942" kp="1"/>
        <position name="arm:elbow_T" joint="arm:elbow_joint" ctrllimited="true" ctrlrange="-2.0942 2.0942" kp="1"/>
        <position name="arm:wrist_1_T" joint="arm:wrist_1_joint" ctrllimited="true" ctrlrange="-3.14 3.14" kp="1"/>
        <position name="arm:wrist_2_T" joint="arm:wrist_2_joint" ctrllimited="true" ctrlrange="-3.14 3.14" kp="1"/>
        <position name="arm:wrist_3_T" joint="arm:wrist_3_joint" ctrllimited="true" ctrlrange="-3.14 3.14" kp="1"/>
        
        <!--<general biasprm="none" biastype="affine" ctrllimited="true" ctrlrange="-2.0942 2.0942" forcelimited="true" forcerange="-10 10" gainprm="1 0 0" joint="arm:shoulder_pan_joint" name="arm:shoulder_pan_T" />
        <general biasprm="none" biastype="affine" ctrllimited="true" ctrlrange="-2.0942 2.0942" forcelimited="true" forcerange="-10 10" gainprm="1 0 0" joint="arm:shoulder_lift_joint" name="arm:shoulder_lift_T" />
        <general biasprm="none" biastype="affine" ctrllimited="true" ctrlrange="-2.0942 2.0942" forcelimited="true" forcerange="-10 10" gainprm="1 0 0" joint="arm:elbow_joint" name="arm:elbow_T" />
        <general biasprm="none" biastype="affine" ctrllimited="true" ctrlrange="-3.14 3.14" forcelimited="true" forcerange="-10 10" gainprm="1 0 0" joint="arm:wrist_1_joint" name="arm:wrist_1_T" />
        <general biasprm="none" biastype="affine" ctrllimited="true" ctrlrange="-3.14 3.14" forcelimited="true" forcerange="-10 10" gainprm="1 0 0" joint="arm:wrist_2_joint" name="arm:wrist_2_T" />
        <general biasprm="none" biastype="affine" ctrllimited="true" ctrlrange="-3.14 3.14" forcelimited="true" forcerange="-10 10" gainprm="1 0 0" joint="arm:wrist_3_joint" name="arm:wrist_3_T" />-->
        <!-- <general ctrllimited="true" ctrlrange="-150 150" forcelimited="true" forcerange="-150 150" gainprm="1" joint="arm:shoulder_pan_joint" name="arm:shoulder_pan_T"/>
        <general ctrllimited="true" ctrlrange="-150 150" forcelimited="true" forcerange="-150 150" gainprm="1" joint="arm:shoulder_lift_joint" name="arm:shoulder_lift_T"/>
        <general ctrllimited="true" ctrlrange="-150 150" forcelimited="true" forcerange="-150 150" gainprm="1" joint="arm:elbow_joint" name="arm:elbow_T"/> -->
        <!-- <general ctrllimited="true" ctrlrange="-28 28" forcelimited="true" forcerange="-28 28" gainprm="1" joint="arm:wrist_1_joint" name="arm:wrist_1_T"/>
        <general ctrllimited="true" ctrlrange="-28 28" forcelimited="true" forcerange="-28 28" gainprm="1" joint="arm:wrist_2_joint" name="arm:wrist_2_T"/>
        <general ctrllimited="true" ctrlrange="-28 28" forcelimited="true" forcerange="-28 28" gainprm="1" joint="arm:wrist_3_joint" name="arm:wrist_3_T"/> -->

        <!--
        <position name="left_gripper_actuator" joint="left_gripper_joint" ctrllimited="true" ctrlrange="0 0.02" />
        <position name="right_gripper_actuator" joint="right_gripper_joint" ctrllimited="true" ctrlrange="-0.02 0" />
        -->

    </actuator>

    <sensor>
        <!-- <torque name="shoulder_sensor" site="shoulder_site"/>
        <torque name="upper_arm_sensor" site="upperarm_site"/>
        <torque name="forearm_sensor" site="forearm_site"/>
        <torque name="wrist_1_sensor" site="wrist_1_site"/>
        <torque name="wrist_2_sensor" site="wrist_2_site"/>
        <torque name="wrist_3_sensor" site="wrist_3_site"/> 
        <actuatorfrc name="shoulder_pan_P_frc" actuator="arm:shoulder_pan_T" />
        <actuatorfrc name="shoulder_lift_P_frc" actuator="arm:shoulder_lift_T" />
        <actuatorfrc name="forearm_P_frc" actuator="arm:elbow_T" />
        <actuatorfrc name="wrist_1_P_frc" actuator="arm:wrist_1_T" />
        <actuatorfrc name="wrist_2_P_frc" actuator="arm:wrist_2_T" />
        <actuatorfrc name="wrist_3_P_frc" actuator="arm:wrist_3_T" />

        <actuatorfrc name="x_force_sensor" actuator="x_force"/>
        <actuatorfrc name="y_force_sensor" actuator="y_force"/>
        <actuatorfrc name="z_force_sensor" actuator="z_force"/>
        <actuatorfrc name="x_torque_sensor" actuator="x_torque"/>
        <actuatorfrc name="y_torque_sensor" actuator="y_torque"/>
        <actuatorfrc name="z_torque_sensor" actuator="z_torque"/> -->
    </sensor>

</mujoco>